package exception_Error;

public class Error4 {

	public static void main(String[] args) {
// nested try and catch block;
//		try {
//			int a=9;
//			int b=0;
//			System.out.println(a/b);
//			try {
//				int number[]=new int[5];
//				System.out.println(number[2]);
//			}
//			catch(ArrayIndexOutOfBoundsException e1) {
//				System.out.println("Array index out of Bounds: ");
//			}
//			try {
//				String s=null;
//				System.out.println(s.length());
//			}
//			catch(NullPointerException e2) {
//				System.out.println(e2);
//			}
//		}
//		catch(ArithmeticException e3) {
//			System.out.println("Arithmatic exception occured");
//		}
//		System.out.println("end of program: ");
	}

}
